Workbook

Sheet Summary
A1: FlowRack Logistics — Warehouse Efficiency Insight
A2: Synthetic practice dataset; findings are illustrative and are not actual FlowRack operational results.
A4: Key Finding | B4: Evidence from EDA | C4: Business Interpretation | D4: Suggested Action
A5: Overall picking time | B5: Average 7.78 min; median 8 min | C5: Typical pick record takes about 8 minutes in this synthetic sample | D5: Monitor average and median by zone and shift
A6: Zone variation | B6: Zone G Cold Storage 10.69 min; Zone A Fast-Moving 5.18 min | C6: Zone-level averages differ substantially; zone conditions may contribute | D6: Review travel path, storage layout, and handling needs in Zone G
A7: Experience | B7: Beginner 9.57 min; Experienced 6.74 min | C7: Beginner records have longer average pick times | D7: Provide onboarding, standard work, and mentoring; avoid assuming causation
A8: Shift | B8: Evening 8.65 min; Morning 7.34 min | C8: Evening shift has the highest average among named shifts | D8: Review staffing, workload mix, and handover practices
A9: Order size | B9: Small 7.56 min; Large 8.01 min | C9: Average difference by size group is modest in this dataset | D9: Evaluate total order completion time as well as per-pick time
A10: Category | B10: Fragile Goods 8.08 min; Bulk Materials 7.53 min | C10: Handling requirements may differ by category | D10: Review fragile-item handling steps and packaging process
A11: Hourly workload | B11: Highest count: 61 picks started at 13:00 | C11: This is a workload proxy, not a direct measure of queue length | D11: Check queue-entry/wait timestamps before making queue claims
A12: Data quality | B12: Unknown shift: 157 records; Unknown experience: 233 records | C12: Missing labels limit the confidence of comparisons | D12: Improve master-data completeness and validation rules

Sheet Existing_PivotTable
A1: order_id | B1: (All)
A3: Count of size | B3: Column Labels
A4: Row Labels | B4: P000001 | C4: P000002 | D4: P000003 | E4: P000004 | F4: P000006 | G4: P000007 | H4: P000008 | I4: P000009 | J4: P000010 | K4: P000011 | L4: P000012 | M4: P000013 | N4: P000015 | O4: P000016 | P4: P000017 | Q4: P000018 | R4: P000019 | S4: P000020 | T4: P000022 | U4: P000023 | V4: P000024 | W4: P000025 | X4: P000026 | Y4: P000028 | Z4: P000029 | AA4: P000030 | AB4: P000031 | AC4: P000032 | AD4: P000034 | AE4: P000035 | AF4: P000037 | AG4: P000038 | AH4: P000040 | AI4: P000041 | AJ4: P000042 | AK4: P000043 | AL4: P000044 | AM4: P000045 | AN4: P000046 | AO4: P000047 | AP4: P000048 | AQ4: P000050 | AR4: P000051 | AS4: P000052 | AT4: P000053 | AU4: P000054 | AV4: P000055 | AW4: P000056 | AX4: P000057 | AY4: P000058 | AZ4: P000059 | BA4: P000060 | BB4: P000061 | BC4: P000062 | BD4: P000063 | BE4: P000064 | BF4: P000065 | BG4: P000066 | BH4: P000068 | BI4: P000069 | BJ4: P000070 | BK4: P000071 | BL4: P000073 | BM4: P000074 | BN4: P000075 | BO4: P000076 | BP4: P000077 | BQ4: P000079 | BR4: P000080 | BS4: P000081 | BT4: P000082 | BU4: P000083 | BV4: P000085 | BW4: P000086 | BX4: P000088 | BY4: P000090 | BZ4: P000091 | CA4: P000092 | CB4: P000093 | CC4: P000094 | CD4: P000095 | CE4: P000096 | CF4: P000097 | CG4: P000098 | CH4: P000099 | CI4: P000100 | CJ4: P000101 | CK4: P000102 | CL4: P000103 | CM4: P000104 | CN4: P000105 | CO4: P000106 | CP4: P000107 | CQ4: P000108 | CR4: P000109 | CS4: P000110 | CT4: P000111 | CU4: P000113 | CV4: P000114 | CW4: P000117 | CX4: P000118 | CY4: P000119 | CZ4: P000120 | DA4: P000121 | DB4: P000122 | DC4: P000123 | DD4: P000124 | DE4: P000125 | DF4: P000126 | DG4: P000128 | DH4: P000129 | DI4: P000130 | DJ4: P000131 | DK4: P000132 | DL4: P000133 | DM4: P000134 | DN4: P000135 | DO4: P000136 | DP4: P000137 | DQ4: P000138 | DR4: P000139 | DS4: P000140 | DT4: P000141 | DU4: P000142 | DV4: P000143 | DW4: P000144 | DX4: P000145 | DY4: P000146 | DZ4: P000147 | EA4: P000148 | EB4: P000149 | EC4: P000150 | ED4: P000152 | EE4: P000153 | EF4: P000154 | EG4: P000155 | EH4: P000156 | EI4: P000157 | EJ4: P000158 | EK4: P000159 | EL4: P000160 | EM4: P000162 | EN4: P000163 | EO4: P000164 | EP4: P000166 | EQ4: P000167 | ER4: P000168 | ES4: P000169 | ET4: P000170 | EU4: P000171 | EV4: P000172 | EW4: P000173 | EX4: P000174 | EY4: P000175 | EZ4: P000176 | FA4: P000177 | FB4: P000178 | FC4: P000179 | FD4: P000180 | FE4: P000181 | FF4: P000182 | FG4: P000183 | FH4: P000184 | FI4: P000185 | FJ4: P000186 | FK4: P000187 | FL4: P000188 | FM4: P000189 | FN4: P000191 | FO4: P000192 | FP4: P000193 | FQ4: P000195 | FR4: P000196 | FS4: P000198 | FT4: P000199 | FU4: P000200 | FV4: P000201 | FW4: P000202 | FX4: P000203 | FY4: P000204 | FZ4: P000205 | GA4: P000206 | GB4: P000207 | GC4: P000208 | GD4: P000209 | GE4: P000210 | GF4: P000211 | GG4: P000212 | GH4: P000213 | GI4: P000214 | GJ4: P000215 | GK4: P000216 | GL4: P000217 | GM4: P000218 | GN4: P000219 | GO4: P000220 | GP4: P000222 | GQ4: P000223 | GR4: P000224 | GS4: P000225 | GT4: P000226 | GU4: P000227 | GV4: P000228 | GW4: P000229 | GX4: P000230 | GY4: P000231 | GZ4: P000233 | HA4: P000234 | HB4: P000235 | HC4: P000236 | HD4: P000237 | HE4: P000238 | HF4: P000239 | HG4: P000240 | HH4: P000241 | HI4: P000243 | HJ4: P000244 | HK4: P000245 | HL4: P000246 | HM4: P000247 | HN4: P000248 | HO4: P000249 | HP4: P000250 | HQ4: P000251 | HR4: P000253 | HS4: P000254 | HT4: P000255 | HU4: P000256 | HV4: P000257 | HW4: P000258 | HX4: P000259 | HY4: P000260 | HZ4: P000261 | IA4: P000262 | IB4: P000263 | IC4: P000264 | ID4: P000265 | IE4: P000266 | IF4: P000267 | IG4: P000268 | IH4: P000269 | II4: P000270 | IJ4: P000271 | IK4: P000272 | IL4: P000273 | IM4: P000275 | IN4: P000276 | IO4: P000277 | IP4: P000278 | IQ4: P000279 | IR4: P000280 | IS4: P000281 | IT4: P000282 | IU4: P000283 | IV4: P000284 | IW4: P000285 | IX4: P000286 | IY4: P000287 | IZ4: P000288 | JA4: P000289 | JB4: P000290 | JC4: P000291 | JD4: P000292 | JE4: P000293 | JF4: P000295 | JG4: P000296 | JH4: P000297 | JI4: P000298 | JJ4: P000299 | JK4: P000300 | JL4: P000301 | JM4: P000302 | JN4: P000303 | JO4: P000305 | JP4: P000306 | JQ4: P000307 | JR4: P000308 | JS4: P000309 | JT4: P000310 | JU4: P000311 | JV4: P000312 | JW4: P000313 | JX4: P000314 | JY4: P000315 | JZ4: P000316 | KA4: P000317 | KB4: P000319 | KC4: P000320 | KD4: P000321 | KE4: P000322 | KF4: P000324 | KG4: P000325 | KH4: P000326 | KI4: P000327 | KJ4: P000328 | KK4: P000329 | KL4: P000330 | KM4: P000331 | KN4: P000332 | KO4: P000333 | KP4: P000334 | KQ4: P000336 | KR4: P000338 | KS4: P000339 | KT4: P000340 | KU4: P000341 | KV4: P000342 | KW4: P000343 | KX4: P000345 | KY4: P000346 | KZ4: P000348 | LA4: P000349 | LB4: P000350 | LC4: P000351 | LD4: P000352 | LE4: P000353 | LF4: P000354 | LG4: P000355 | LH4: P000356 | LI4: P000357 | LJ4: P000358 | LK4: P000359 | LL4: P000360 | LM4: P000361 | LN4: P000362 | LO4: P000363 | LP4: P000364 | LQ4: P000365 | LR4: P000366 | LS4: P000367 | LT4: P000368 | LU4: P000369 | LV4: P000370 | LW4: P000371 | LX4: P000372 | LY4: P000373 | LZ4: P000374 | MA4: P000375 | MB4: P000376 | MC4: P000379 | MD4: P000380 | ME4: P000381 | MF4: P000382 | MG4: P000383 | MH4: P000384 | MI4: P000385 | MJ4: P000386 | MK4: P000387 | ML4: P000388 | MM4: P000389 | MN4: P000390 | MO4: P000391 | MP4: P000392 | MQ4: P000393 | MR4: P000394 | MS4: P000395 | MT4: P000397 | MU4: P000398 | MV4: P000399 | MW4: P000400 | MX4: P000401 | MY4: P000402 | MZ4: P000403 | NA4: P000404 | NB4: P000405 | NC4: P000406 | ND4: P000408 | NE4: P000409 | NF4: P000410 | NG4: P000411 | NH4: P000412 | NI4: P000413 | NJ4: P000414 | NK4: P000415 | NL4: P000416 | NM4: P000418 | NN4: P000419 | NO4: P000420 | NP4: P000421 | NQ4: P000422 | NR4: P000423 | NS4: P000424 | NT4: P000425 | NU4: P000426 | NV4: P000427 | NW4: P000428 | NX4: P000430 | NY4: P000432 | NZ4: P000433 | OA4: P000434 | OB4: P000435 | OC4: P000436 | OD4: P000437 | OE4: P000438 | OF4: P000440 | OG4: P000441 | OH4: P000442 | OI4: P000443 | OJ4: P000444 | OK4: P000445 | OL4: P000447 | OM4: P000448 | ON4: P000449 | OO4: P000450 | OP4: P000451 | OQ4: P000452 | OR4: P000453 | OS4: P000454 | OT4: P000455 | OU4: P000456 | OV4: P000457 | OW4: P000458 | OX4: P000459 | OY4: P000460 | OZ4: P000461 | PA4: P000464 | PB4: P000467 | PC4: P000468 | PD4: P000469 | PE4: P000470 | PF4: P000471 | PG4: P000472 | PH4: P000473 | PI4: P000474 | PJ4: P000475 | PK4: P000476 | PL4: P000477 | PM4: P000478 | PN4: P000479 | PO4: P000480 | PP4: P000483 | PQ4: P000484 | PR4: P000485 | PS4: P000486 | PT4: P000488 | PU4: P000489 | PV4: P000490 | PW4: P000491 | PX4: P000492 | PY4: P000493 | PZ4: P000495 | QA4: P000496 | QB4: P000497 | QC4: P000498 | QD4: P000499 | QE4: P000500 | QF4: P000501 | QG4: P000502 | QH4: P000503 | QI4: P000504 | QJ4: P000505 | QK4: P000507 | QL4: P000508 | QM4: P000509 | QN4: P000510 | QO4: P000511 | QP4: P000512 | QQ4: P000513 | QR4: P000514 | QS4: P000515 | QT4: P000516 | QU4: P000517 | QV4: P000518 | QW4: P000519 | QX4: P000520 | QY4: P000521 | QZ4: P000522 | RA4: P000523 | RB4: P000524 | RC4: P000525 | RD4: P000526 | RE4: P000527 | RF4: P000528 | RG4: P000529 | RH4: P000530 | RI4: P000532 | RJ4: P000533 | RK4: P000534 | RL4: P000535 | RM4: P000536 | RN4: P000537 | RO4: P000538 | RP4: P000540 | RQ4: P000541 | RR4: P000542 | RS4: P000543 | RT4: P000544 | RU4: P000545 | RV4: P000546 | RW4: P000547 | RX4: P000548 | RY4: P000549 | RZ4: P000550 | SA4: P000551 | SB4: P000552 | SC4: P000553 | SD4: P000554 | SE4: P000556 | SF4: P000557 | SG4: P000558 | SH4: P000560 | SI4: P000561 | SJ4: P000562 | SK4: P000563 | SL4: P000564 | SM4: P000565 | SN4: P000566 | SO4: P000567 | SP4: P000568 | SQ4: P000570 | SR4: P000571 | SS4: P000572 | ST4: P000574 | SU4: P000575 | SV4: P000576 | SW4: P000577 | SX4: P000578 | SY4: P000579 | SZ4: P000580 | TA4: P000581 | TB4: P000582 | TC4: P000584 | TD4: P000585 | TE4: P000586 | TF4: P000587 | TG4: P000588 | TH4: P000590 | TI4: P000591 | TJ4: P000592 | TK4: P000593 | TL4: P000595 | TM4: P000596 | TN4: P000597 | TO4: P000598 | TP4: P000599 | TQ4: P000600 | TR4: P000601 | TS4: P000602 | TT4: P000603 | TU4: P000604 | TV4: P000605 | TW4: P000606 | TX4: P000607 | TY4: P000608 | TZ4: P000609 | UA4: P000611 | UB4: P000612 | UC4: P000613 | UD4: P000614 | UE4: P000615 | UF4: P000616 | UG4: P000617 | UH4: P000619 | UI4: P000620 | UJ4: P000621 | UK4: P000622 | UL4: P000623 | UM4: P000624 | UN4: P000625 | UO4: P000626 | UP4: P000627 | UQ4: P000628 | UR4: P000629 | US4: P000630 | UT4: P000631 | UU4: P000632 | UV4: P000633 | UW4: P000635 | UX4: P000636 | UY4: P000637 | UZ4: P000639 | VA4: P000640 | VB4: P000641 | VC4: P000642 | VD4: P000643 | VE4: P000644 | VF4: P000645 | VG4: P000646 | VH4: P000647 | VI4: P000648 | VJ4: P000650 | VK4: P000651 | VL4: P000652 | VM4: P000654 | VN4: P000655 | VO4: P000656 | VP4: P000657 | VQ4: P000658 | VR4: P000659 | VS4: P000660 | VT4: P000661 | VU4: P000663 | VV4: P000664 | VW4: P000665 | VX4: P000666 | VY4: P000667 | VZ4: P000668 | WA4: P000669 | WB4: P000670 | WC4: P000672 | WD4: P000673 | WE4: P000674 | WF4: P000675 | WG4: P000677 | WH4: P000678 | WI4: P000679 | WJ4: P000681 | WK4: P000682 | WL4: P000683 | WM4: P000684 | WN4: P000685 | WO4: P000686 | WP4: P000688 | WQ4: P000689 | WR4: P000690 | WS4: P000691 | WT4: P000692 | WU4: P000693 | WV4: P000694 | WW4: P000695 | WX4: P000696 | WY4: P000697 | WZ4: P000698 | XA4: P000699 | XB4: P000700 | XC4: P000701 | XD4: P000702 | XE4: P000704 | XF4: P000705 | XG4: P000706 | XH4: P000707 | XI4: P000708 | XJ4: P000709 | XK4: P000710 | XL4: P000712 | XM4: P000713 | XN4: P000714 | XO4: P000715 | XP4: P000716 | XQ4: P000717 | XR4: P000718 | XS4: P000719 | XT4: P000720 | XU4: P000722 | XV4: P000723 | XW4: P000725 | XX4: P000727 | XY4: P000728 | XZ4: P000729 | YA4: P000730 | YB4: P000731 | YC4: P000732 | YD4: P000733 | YE4: P000734 | YF4: P000735 | YG4: P000736 | YH4: P000737 | YI4: P000738 | YJ4: P000739 | YK4: P000740 | YL4: P000741 | YM4: P000743 | YN4: P000744 | YO4: P000745 | YP4: P000746 | YQ4: P000747 | YR4: P000748 | YS4: P000749 | YT4: P000750 | YU4: P000751 | YV4: P000752 | YW4: P000753 | YX4: P000754 | YY4: P000755 | YZ4: P000756 | ZA4: P000757 | ZB4: P000759 | ZC4: P000760 | ZD4: P000761 | ZE4: P000762 | ZF4: P000763 | ZG4: P000764 | ZH4: P000765 | ZI4: P000766 | ZJ4: P000769 | ZK4: P000770 | ZL4: P000771 | ZM4: P000774 | ZN4: P000776 | ZO4: P000777 | ZP4: P000778 | ZQ4: P000779 | ZR4: P000781 | ZS4: P000782 | ZT4: P000783 | ZU4: P000784 | ZV4: P000785 | ZW4: P000786 | ZX4: P000788 | ZY4: P000789 | ZZ4: P000790 | AAA4: P000791 | AAB4: P000792 | AAC4: P000793 | AAD4: P000794 | AAE4: P000795 | AAF4: P000796 | AAG4: P000797 | AAH4: P000798 | AAI4: P000799 | AAJ4: P000800 | AAK4: P000801 | AAL4: P000803 | AAM4: P000804 | AAN4: P000806 | AAO4: P000808 | AAP4: P000809 | AAQ4: P000810 | AAR4: P000811 | AAS4: P000812 | AAT4: P000813 | AAU4: P000814 | AAV4: P000815 | AAW4: P000816 | AAX4: P000817 | AAY4: P000818 | AAZ4: P000820 | ABA4: P000822 | ABB4: P000823 | ABC4: P000824 | ABD4: P000825 | ABE4: P000826 | ABF4: P000827 | ABG4: P000828 | ABH4: P000829 | ABI4: P000830 | ABJ4: P000832 | ABK4: P000833 | ABL4: P000835 | ABM4: P000836 | ABN4: P000837 | ABO4: P000838 | ABP4: P000839 | ABQ4: P000840 | ABR4: P000841 | ABS4: P000842 | ABT4: P000843 | ABU4: P000844 | ABV4: P000845 | ABW4: P000846 | ABX4: P000847 | ABY4: P000848 | ABZ4: P000849 | ACA4: P000850 | ACB4: P000851 | ACC4: P000852 | ACD4: P000853 | ACE4: P000854 | ACF4: P000856 | ACG4: P000857 | ACH4: P000858 | ACI4: P000859 | ACJ4: P000860 | ACK4: P000861 | ACL4: P000862 | ACM4: P000863 | ACN4: P000864 | ACO4: P000865 | ACP4: P000866 | ACQ4: P000867 | ACR4: P000868 | ACS4: P000869 | ACT4: P000870 | ACU4: P000872 | ACV4: P000873 | ACW4: P000874 | ACX4: P000875 | ACY4: P000876 | ACZ4: P000877 | ADA4: P000878 | ADB4: P000880 | ADC4: P000881 | ADD4: P000882 | ADE4: P000883 | ADF4: P000884 | ADG4: P000885 | ADH4: P000886 | ADI4: P000887 | ADJ4: P000888 | ADK4: P000889 | ADL4: P000890 | ADM4: P000891 | ADN4: P000892 | ADO4: P000893 | ADP4: P000894 | ADQ4: P000895 | ADR4: P000896 | ADS4: P000897 | ADT4: P000898 | ADU4: P000899 | ADV4: P000900 | ADW4: P000901 | ADX4: P000902 | ADY4: P000903 | ADZ4: P000904 | AEA4: P000905 | AEB4: P000906 | AEC4: P000907 | AED4: P000908 | AEE4: P000909 | AEF4: P000911 | AEG4: P000912 | AEH4: P000915 | AEI4: P000916 | AEJ4: P000917 | AEK4: P000919 | AEL4: P000920 | AEM4: P000921 | AEN4: P000923 | AEO4: P000924 | AEP4: P000925 | AEQ4: P000926 | AER4: P000927 | AES4: P000928 | AET4: P000929 | AEU4: P000930 | AEV4: P000931 | AEW4: P000932 | AEX4: P000933 | AEY4: P000934 | AEZ4: P000935 | AFA4: P000936 | AFB4: P000937 | AFC4: P000938 | AFD4: P000940 | AFE4: P000941 | AFF4: P000942 | AFG4: P000943 | AFH4: P000944 | AFI4: P000945 | AFJ4: P000946 | AFK4: P000947 | AFL4: P000948 | AFM4: P000949 | AFN4: P000950 | AFO4: P000952 | AFP4: P000953 | AFQ4: P000954 | AFR4: P000955 | AFS4: P000956 | AFT4: P000957 | AFU4: P000958 | AFV4: P000960 | AFW4: P000961 | AFX4: P000962 | AFY4: P000963 | AFZ4: P000964 | AGA4: P000967 | AGB4: P000968 | AGC4: P000969 | AGD4: P000970 | AGE4: P000971 | AGF4: P000973 | AGG4: P000974 | AGH4: P000976 | AGI4: P000977 | AGJ4: P000978 | AGK4: P000979 | AGL4: P000981 | AGM4: P000982 | AGN4: P000983 | AGO4: P000984 | AGP4: P000987 | AGQ4: P000988 | AGR4: P000989 | AGS4: P000990 | AGT4: P000991 | AGU4: P000992 | AGV4: P000993 | AGW4: P000994 | AGX4: P000995 | AGY4: P000996 | AGZ4: P000997 | AHA4: P000998 | AHB4: P000999 | AHC4: P001000 | AHD4: P001001 | AHE4: P001003 | AHF4: P001004 | AHG4: P001005 | AHH4: P001006 | AHI4: P001007 | AHJ4: P001009 | AHK4: P001010 | AHL4: P001011 | AHM4: P001012 | AHN4: P001013 | AHO4: P001014 | AHP4: P001015 | AHQ4: P001016 | AHR4: P001017 | AHS4: P001018 | AHT4: P001019 | AHU4: P001020 | AHV4: P001021 | AHW4: P001022 | AHX4: P001023 | AHY4: P001024 | AHZ4: P001025 | AIA4: P001026 | AIB4: P001027 | AIC4: P001028 | AID4: P001029 | AIE4: P001030 | AIF4: P001031 | AIG4: P001033 | AIH4: P001035 | AII4: P001036 | AIJ4: P001037 | AIK4: P001038 | AIL4: P001039 | AIM4: P001040 | AIN4: P001041 | AIO4: P001042 | AIP4: P001043 | AIQ4: P001044 | AIR4: P001045 | AIS4: P001046 | AIT4: P001047 | AIU4: P001048 | AIV4: P001049 | AIW4: P001050 | AIX4: P001051 | AIY4: P001052 | AIZ4: P001053 | AJA4: P001054 | AJB4: P001055 | AJC4: P001056 | AJD4: P001057 | AJE4: P001058 | AJF4: P001059 | AJG4: P001060 | AJH4: P001061 | AJI4: P001062 | AJJ4: P001064 | AJK4: P001065 | AJL4: P001066 | AJM4: P001067 | AJN4: P001068 | AJO4: P001069 | AJP4: P001070 | AJQ4: P001071 | AJR4: P001072 | AJS4: P001073 | AJT4: P001074 | AJU4: P001075 | AJV4: P001077 | AJW4: P001079 | AJX4: P001080 | AJY4: P001081 | AJZ4: P001082 | AKA4: P001083 | AKB4: P001084 | AKC4: P001085 | AKD4: P001086 | AKE4: P001087 | AKF4: P001088 | AKG4: P001090 | AKH4: P001091 | AKI4: P001092 | AKJ4: P001093 | AKK4: P001094 | AKL4: P001096 | AKM4: P001097 | AKN4: P001098 | AKO4: P001099 | AKP4: P001100 | AKQ4: P001102 | AKR4: P001103 | AKS4: P001104 | AKT4: P001105 | AKU4: P001106 | AKV4: P001107 | AKW4: P001108 | AKX4: P001109 | AKY4: P001110 | AKZ4: P001111 | ALA4: P001112 | ALB4: P001114 | ALC4: P001115 | ALD4: P001116 | ALE4: P001118 | ALF4: P001119 | ALG4: P001120 | ALH4: P001121 | ALI4: P001122 | ALJ4: P001123 | ALK4: P001124 | ALL4: P001125 | ALM4: P001126 | ALN4: P001127 | ALO4: P001128 | ALP4: P001129 | ALQ4: P001130 | ALR4: P001131 | ALS4: P001132 | ALT4: P001133 | ALU4: P001134 | ALV4: P001136 | ALW4: P001137 | ALX4: P001138 | ALY4: P001139 | ALZ4: P001140 | AMA4: Grand Total
A5: W001 | E5: 1 | M5: 1 | AU5: 1 | BL5: 1 | CU5: 1 | EA5: 1 | EU5: 1 | FO5: 1 | FS5: 1 | GR5: 1 | GV5: 1 | JM5: 1 | KY5: 1 | LD5: 1 | LF5: 1 | QM5: 1 | RK5: 1 | SE5: 1 | SG5: 1 | UB5: 1 | UR5: 1 | VI5: 1 | VM5: 1 | XP5: 1 | XT5: 1 | YD5: 1 | ZH5: 1 | AEP5: 1 | AFQ5: 1 | AFX5: 1 | AGW5: 1 | AGY5: 1 | AIY5: 1 | AJR5: 1 | AJX5: 1 | AKE5: 1 | AMA5: 36
A6: W002 | AV6: 1 | BK6: 1 | BZ6: 1 | CY6: 1 | FM6: 1 | HL6: 1 | IG6: 1 | JP6: 1 | KI6: 1 | LC6: 1 | SD6: 1 | VU6: 1 | WG6: 1 | XB6: 1 | XI6: 1 | YE6: 1 | YI6: 1 | ZU6: 1 | AAP6: 1 | AAS6: 1 | ACC6: 1 | AGG6: 1 | AGI6: 1 | AGX6: 1 | AIG6: 1 | AIS6: 1 | AJZ6: 1 | AKR6: 1 | ALA6: 1 | ALD6: 1 | ALZ6: 1 | AMA6: 31
A7: W003 | W7: 1 | BR7: 1 | CB7: 1 | CT7: 1 | EC7: 1 | EE7: 1 | EG7: 1 | FW7: 1 | GM7: 1 | GQ7: 1 | HO7: 1 | HV7: 1 | IU7: 1 | NL7: 1 | QH7: 1 | RG7: 1 | RS7: 1 | VB7: 1 | VO7: 1 | WH7: 1 | WX7: 1 | XC7: 1 | ZD7: 1 | ADY7: 1 | AEU7: 1 | AGB7: 1 | AGH7: 1 | AIJ7: 1 | AIQ7: 1 | AJV7: 1 | ALM7: 1 | AMA7: 31
A8: W004 | AO8: 1 | BM8: 1 | BV8: 1 | BW8: 1 | FT8: 1 | HP8: 1 | HT8: 1 | HY8: 1 | KE8: 1 | KV8: 1 | LA8: 1 | LR8: 1 | MR8: 1 | NS8: 1 | OA8: 1 | OU8: 1 | QB8: 1 | QL8: 1 | QR8: 1 | QV8: 1 | TR8: 1 | VT8: 1 | WA8: 1 | WW8: 1 | YZ8: 1 | AAB8: 1 | AAL8: 1 | ACQ8: 1 | AJH8: 1 | ALW8: 1 | AMA8: 30
A9: W005 | N9: 1 | U9: 1 | AR9: 1 | AX9: 1 | BC9: 1 | DL9: 1 | DX9: 1 | EX9: 1 | GI9: 1 | GS9: 1 | HE9: 1 | KD9: 1 | KT9: 1 | MM9: 1 | PU9: 1 | RM9: 1 | SY9: 1 | UT9: 1 | WV9: 1 | XN9: 1 | XU9: 1 | YY9: 1 | ZY9: 1 | AAR9: 1 | ACF9: 1 | AEI9: 1 | AEQ9: 1 | AFE9: 1 | AHY9: 1 | AIK9: 1 | AIO9: 1 | ALO9: 1 | AMA9: 32
A10: W006 | O10: 1 | S10: 1 | BF10: 1 | CM10: 1 | DZ10: 1 | FB10: 1 | LL10: 1 | NJ10: 1 | NU10: 1 | OW10: 1 | QI10: 1 | QJ10: 1 | QN10: 1 | TA10: 1 | UJ10: 1 | WZ10: 1 | XK10: 1 | ZM10: 1 | ABB10: 1 | ADL10: 1 | ADV10: 1 | AEV10: 1 | AHP10: 1 | AHV10: 1 | AKP10: 1 | ALJ10: 1 | ALR10: 1 | ALU10: 1 | AMA10: 28
A11: W007 | G11: 1 | K11: 1 | V11: 1 | Z11: 1 | BE11: 1 | BH11: 1 | BT11: 1 | CX11: 1 | DB11: 1 | DK11: 1 | DW11: 1 | EM11: 1 | ET11: 1 | GG11: 1 | IC11: 1 | IQ11: 1 | LT11: 1 | MB11: 1 | ND11: 1 | NH11: 1 | NT11: 1 | PL11: 1 | PT11: 1 | SK11: 1 | UM11: 1 | VF11: 1 | WR11: 1 | XG11: 1 | XJ11: 1 | XR11: 1 | YA11: 1 | YF11: 1 | AAH11: 1 | ABL11: 1 | ACT11: 1 | AFB11: 1 | AFJ11: 1 | AFK11: 1 | AHB11: 1 | AHL11: 1 | AJB11: 1 | AKO11: 1 | ALG11: 1 | AMA11: 43
A12: W008 | AC12: 1 | BX12: 1 | DU12: 1 | DY12: 1 | GZ12: 1 | IK12: 1 | IV12: 1 | JE12: 1 | LE12: 1 | MJ12: 1 | MO12: 1 | MS12: 1 | NN12: 1 | NW12: 1 | OQ12: 1 | OZ12: 1 | PE12: 1 | PH12: 1 | QO12: 1 | RB12: 1 | TO12: 1 | VH12: 1 | WL12: 1 | YX12: 1 | ZJ12: 1 | ZV12: 1 | ZX12: 1 | AAJ12: 1 | AAO12: 1 | ABU12: 1 | ACK12: 1 | AEB12: 1 | AFM12: 1 | AHH12: 1 | AHI12: 1 | AHX12: 1 | AKB12: 1 | AKQ12: 1 | AMA12: 38
A13: W009 | AH13: 1 | DN13: 1 | HN13: 1 | IY13: 1 | ML13: 1 | NG13: 1 | NO13: 1 | NY13: 1 | OL13: 1 | PN13: 1 | QP13: 1 | QZ13: 1 | RP13: 1 | SA13: 1 | SN13: 1 | SO13: 1 | TH13: 1 | US13: 1 | UY13: 1 | XW13: 1 | YB13: 1 | YO13: 1 | ZC13: 1 | ZQ13: 1 | AAC13: 1 | AAF13: 1 | AAU13: 1 | ABK13: 1 | ABX13: 1 | ACG13: 1 | AFG13: 1 | AHZ13: 1 | AIT13: 1 | ALX13: 1 | AMA13: 34
A14: W010 | P14: 1 | Y14: 1 | AK14: 1 | AZ14: 1 | DQ14: 1 | EQ14: 1 | FN14: 1 | HG14: 1 | IO14: 1 | JJ14: 1 | JN14: 1 | KM14: 1 | MW14: 1 | OI14: 1 | QA14: 1 | RT14: 1 | RU14: 1 | RW14: 1 | TG14: 1 | TK14: 1 | UH14: 1 | UN14: 1 | XM14: 1 | ABI14: 1 | ACU14: 1 | AEW14: 1 | AGN14: 1 | AHD14: 1 | AJC14: 1 | ALK14: 1 | AMA14: 30
A15: W011 | CJ15: 1 | CL15: 1 | CN15: 1 | CW15: 1 | FQ15: 1 | HF15: 1 | JZ15: 1 | LM15: 1 | MH15: 1 | MY15: 1 | TY15: 1 | VD15: 1 | VX15: 1 | YJ15: 1 | ABF15: 1 | ABG15: 1 | ABP15: 1 | ACA15: 1 | ADG15: 1 | AEK15: 1 | AGJ15: 1 | AGR15: 1 | AKC15: 1 | AKV15: 1 | ALH15: 1 | AMA15: 25
A16: W012 | CQ16: 1 | CV16: 1 | DM16: 1 | FD16: 1 | FE16: 1 | FF16: 1 | FL16: 1 | GW16: 1 | JS16: 1 | JX16: 1 | KH16: 1 | NA16: 1 | OF16: 1 | OO16: 1 | PB16: 1 | PX16: 1 | RH16: 1 | RY16: 1 | SF16: 1 | TE16: 1 | TZ16: 1 | UF16: 1 | YW16: 1 | ZP16: 1 | ACV16: 1 | ADR16: 1 | AEJ16: 1 | AEN16: 1 | AGE16: 1 | AHJ16: 1 | AJW16: 1 | AKX16: 1 | ALT16: 1 | AMA16: 33
A17: W013 | R17: 1 | AY17: 1 | BO17: 1 | CD17: 1 | DV17: 1 | FG17: 1 | HQ17: 1 | MF17: 1 | MI17: 1 | OG17: 1 | OV17: 1 | PA17: 1 | PJ17: 1 | PK17: 1 | TF17: 1 | TI17: 1 | TQ17: 1 | VC17: 1 | XY17: 1 | ZO17: 1 | AAG17: 1 | AEC17: 1 | AGZ17: 1 | AJK17: 1 | AJL17: 1 | AKG17: 1 | ALB17: 1 | ALL17: 1 | AMA17: 28
A18: W014 | AW18: 1 | BN18: 1 | CZ18: 1 | GB18: 1 | HJ18: 1 | HZ18: 1 | KB18: 1 | MV18: 1 | OK18: 1 | OT18: 1 | QG18: 1 | RX18: 1 | SV18: 1 | TJ18: 1 | WC18: 1 | WF18: 1 | XX18: 1 | AAD18: 1 | ABQ18: 1 | ABW18: 1 | ACJ18: 1 | ACX18: 1 | ADF18: 1 | ADU18: 1 | AEG18: 1 | AFL18: 1 | AFS18: 1 | AGD18: 1 | AHE18: 1 | AHN18: 1 | AHR18: 1 | AID18: 1 | AIN18: 1 | AJE18: 1 | AJG18: 1 | AKJ18: 1 | AMA18: 36
A19: W015 | CP19: 1 | DC19: 1 | DG19: 1 | EV19: 1 | FY19: 1 | HA19: 1 | HK19: 1 | IB19: 1 | IW19: 1 | JD19: 1 | NP19: 1 | OD19: 1 | PY19: 1 | QU19: 1 | QY19: 1 | RV19: 1 | TC19: 1 | UC19: 1 | WN19: 1 | YK19: 1 | ZA19: 1 | AAE19: 1 | AAY19: 1 | ACE19: 1 | ACL19: 1 | ADC19: 1 | ADJ19: 1 | ADK19: 1 | AEL19: 1 | AHA19: 1 | AHU19: 1 | AKI19: 1 | AMA19: 32
A20: W016 | AQ20: 1 | BU20: 1 | DP20: 1 | EF20: 1 | GA20: 1 | GJ20: 1 | KO20: 1 | KR20: 1 | KX20: 1 | LI20: 1 | LN20: 1 | LV20: 1 | NK20: 1 | OX20: 1 | RE20: 1 | RZ20: 1 | ZE20: 1 | ZK20: 1 | AAT20: 1 | ABJ20: 1 | ABO20: 1 | ADO20: 1 | AFD20: 1 | AFF20: 1 | AJJ20: 1 | AJP20: 1 | AJS20: 1 | AJY20: 1 | ALI20: 1 | AMA20: 29
A21: W017 | BD21: 1 | DI21: 1 | EL21: 1 | EN21: 1 | FC21: 1 | ID21: 1 | JR21: 1 | JY21: 1 | NR21: 1 | OH21: 1 | PM21: 1 | QD21: 1 | UX21: 1 | VL21: 1 | AAI21: 1 | ACS21: 1 | AER21: 1 | AFA21: 1 | AFC21: 1 | AFZ21: 1 | AGC21: 1 | AGL21: 1 | AGT21: 1 | AJN21: 1 | AKW21: 1 | ALC21: 1 | AMA21: 26
A22: W018 | BQ22: 1 | BS22: 1 | CO22: 1 | EJ22: 1 | ER22: 1 | GE22: 1 | GP22: 1 | HH22: 1 | HW22: 1 | IH22: 1 | LB22: 1 | LU22: 1 | MN22: 1 | NC22: 1 | OS22: 1 | PG22: 1 | QX22: 1 | SB22: 1 | SQ22: 1 | SU22: 1 | SX22: 1 | TL22: 1 | UI22: 1 | VG22: 1 | VN22: 1 | YL22: 1 | YQ22: 1 | ZF22: 1 | AAK22: 1 | AAW22: 1 | ABA22: 1 | ACD22: 1 | ACY22: 1 | ACZ22: 1 | AED22: 1 | AFR22: 1 | AGV22: 1 | AHT22: 1 | AIZ22: 1 | AJD22: 1 | AJF22: 1 | AKA22: 1 | AMA22: 42
A23: W019 | H23: 1 | I23: 1 | AE23: 1 | AT23: 1 | CE23: 1 | GH23: 1 | HI23: 1 | IF23: 1 | KW23: 1 | MQ23: 1 | NI23: 1 | PD23: 1 | PV23: 1 | QF23: 1 | TB23: 1 | TM23: 1 | TV23: 1 | TW23: 1 | VA23: 1 | YR23: 1 | YV23: 1 | AAM23: 1 | ACR23: 1 | ADP23: 1 | AEX23: 1 | AEZ23: 1 | AFW23: 1 | AGM23: 1 | AGU23: 1 | AHW23: 1 | AKD23: 1 | AKK23: 1 | AKY23: 1 | AMA23: 33
A24: W020 | L24: 1 | AA24: 1 | AB24: 1 | BB24: 1 | EH24: 1 | HD24: 1 | IN24: 1 | JA24: 1 | MZ24: 1 | OM24: 1 | PF24: 1 | PQ24: 1 | SW24: 1 | UZ24: 1 | VE24: 1 | WK24: 1 | XQ24: 1 | ZI24: 1 | AAN24: 1 | AAX24: 1 | ABV24: 1 | ADD24: 1 | ADM24: 1 | AGF24: 1 | AGO24: 1 | AIL24: 1 | AMA24: 26
A25: W021 | AP25: 1 | CA25: 1 | ED25: 1 | EP25: 1 | EY25: 1 | IJ25: 1 | KL25: 1 | KU25: 1 | KZ25: 1 | LJ25: 1 | LY25: 1 | LZ25: 1 | MK25: 1 | MU25: 1 | OB25: 1 | OR25: 1 | PI25: 1 | PW25: 1 | UD25: 1 | UL25: 1 | WJ25: 1 | WM25: 1 | ZZ25: 1 | ABY25: 1 | AEY25: 1 | AFI25: 1 | AFT25: 1 | AGK25: 1 | AIB25: 1 | AIP25: 1 | AKH25: 1 | AMA25: 31
A26: W022 | F26: 1 | AI26: 1 | AJ26: 1 | CC26: 1 | EI26: 1 | FH26: 1 | GD26: 1 | JG26: 1 | KF26: 1 | KK26: 1 | KN26: 1 | LK26: 1 | NX26: 1 | RD26: 1 | RL26: 1 | RN26: 1 | RR26: 1 | SP26: 1 | UK26: 1 | UU26: 1 | VK26: 1 | WY26: 1 | XD26: 1 | YN26: 1 | AAZ26: 1 | ABC26: 1 | ABT26: 1 | AEF26: 1 | AEM26: 1 | AHC26: 1 | AHO26: 1 | AHS26: 1 | AIU26: 1 | AKN26: 1 | AKZ26: 1 | AMA26: 35
A27: W023 | Q27: 1 | DE27: 1 | GC27: 1 | GK27: 1 | IE27: 1 | JK27: 1 | KJ27: 1 | LG27: 1 | LH27: 1 | MD27: 1 | PZ27: 1 | QS27: 1 | RQ27: 1 | SH27: 1 | UV27: 1 | XA27: 1 | YC27: 1 | ZT27: 1 | ACH27: 1 | ACI27: 1 | ADE27: 1 | ADI27: 1 | AGA27: 1 | ALN27: 1 | ALV27: 1 | AMA27: 25
A28: W024 | T28: 1 | CG28: 1 | CK28: 1 | DJ28: 1 | DO28: 1 | DR28: 1 | DS28: 1 | GO28: 1 | HC28: 1 | HX28: 1 | IP28: 1 | IX28: 1 | JH28: 1 | JW28: 1 | KP28: 1 | LP28: 1 | OE28: 1 | OP28: 1 | QT28: 1 | RJ28: 1 | SM28: 1 | VP28: 1 | WB28: 1 | WD28: 1 | ZG28: 1 | ZR28: 1 | ZW28: 1 | AAV28: 1 | ADQ28: 1 | ADT28: 1 | AII28: 1 | AJA28: 1 | AJM28: 1 | AMA28: 33
A29: W025 | AL29: 1 | BP29: 1 | CR29: 1 | EW29: 1 | FJ29: 1 | FU29: 1 | GF29: 1 | GT29: 1 | GY29: 1 | JU29: 1 | LW29: 1 | MC29: 1 | PR29: 1 | QK29: 1 | RF29: 1 | ST29: 1 | TD29: 1 | TT29: 1 | WQ29: 1 | WT29: 1 | XF29: 1 | XZ29: 1 | ACM29: 1 | ACO29: 1 | ADN29: 1 | AFU29: 1 | AFV29: 1 | AGQ29: 1 | AHK29: 1 | AJU29: 1 | AKS29: 1 | AMA29: 31
A30: W026 | AD30: 1 | AN30: 1 | BG30: 1 | CF30: 1 | CH30: 1 | CS30: 1 | DD30: 1 | EK30: 1 | JC30: 1 | JT30: 1 | JV30: 1 | OC30: 1 | ON30: 1 | OY30: 1 | PO30: 1 | QE30: 1 | SI30: 1 | SJ30: 1 | TU30: 1 | VW30: 1 | WO30: 1 | AAA30: 1 | ABR30: 1 | AFY30: 1 | AHG30: 1 | AIM30: 1 | AJQ30: 1 | AKF30: 1 | AMA30: 28
A31: W027 | DH31: 1 | GL31: 1 | GN31: 1 | HU31: 1 | IT31: 1 | JO31: 1 | KA31: 1 | LQ31: 1 | NE31: 1 | NQ31: 1 | RA31: 1 | SR31: 1 | TS31: 1 | UG31: 1 | WU31: 1 | XS31: 1 | YH31: 1 | ADA31: 1 | AIV31: 1 | AIX31: 1 | AJT31: 1 | ALY31: 1 | AMA31: 22
A32: W028 | BY32: 1 | DF32: 1 | EZ32: 1 | HS32: 1 | MA32: 1 | ME32: 1 | MG32: 1 | MX32: 1 | NF32: 1 | PP32: 1 | UE32: 1 | UP32: 1 | VJ32: 1 | VY32: 1 | VZ32: 1 | WS32: 1 | XO32: 1 | YM32: 1 | ZB32: 1 | AAQ32: 1 | ABH32: 1 | ABM32: 1 | AEE32: 1 | AEH32: 1 | AEO32: 1 | AES32: 1 | AIE32: 1 | AJO32: 1 | AKM32: 1 | AMA32: 29
A33: W029 | B33: 1 | C33: 1 | AF33: 1 | AG33: 1 | AM33: 1 | BJ33: 1 | CI33: 1 | EB33: 1 | GU33: 1 | HM33: 1 | IR33: 1 | IS33: 1 | JL33: 1 | JQ33: 1 | KS33: 1 | LO33: 1 | MT33: 1 | NB33: 1 | NM33: 1 | OJ33: 1 | QQ33: 1 | UQ33: 1 | VS33: 1 | VV33: 1 | XE33: 1 | XH33: 1 | XV33: 1 | YG33: 1 | YT33: 1 | YU33: 1 | ZN33: 1 | ABD33: 1 | ABS33: 1 | ABZ33: 1 | AFH33: 1 | AHM33: 1 | AIW33: 1 | AKL33: 1 | AKU33: 1 | ALP33: 1 | ALS33: 1 | AMA33: 41
A34: W030 | AS34: 1 | BI34: 1 | DT34: 1 | FK34: 1 | FP34: 1 | FX34: 1 | FZ34: 1 | HB34: 1 | IA34: 1 | II34: 1 | IM34: 1 | JF34: 1 | KG34: 1 | KQ34: 1 | LX34: 1 | SL34: 1 | TP34: 1 | VQ34: 1 | VR34: 1 | WE34: 1 | YS34: 1 | ZL34: 1 | ACB34: 1 | ACN34: 1 | ACW34: 1 | ADH34: 1 | ADW34: 1 | AFO34: 1 | AGS34: 1 | AHF34: 1 | AIA34: 1 | AIF34: 1 | ALE34: 1 | ALF34: 1 | AMA34: 34
A35: W031 | X35: 1 | BA35: 1 | ES35: 1 | FI35: 1 | FV35: 1 | GX35: 1 | IL35: 1 | JB35: 1 | NV35: 1 | PC35: 1 | QW35: 1 | RO35: 1 | TX35: 1 | UA35: 1 | UO35: 1 | XL35: 1 | ZS35: 1 | ABE35: 1 | ACP35: 1 | AFN35: 1 | AFP35: 1 | AIR35: 1 | ALQ35: 1 | AMA35: 23
A36: W032 | D36: 1 | J36: 1 | DA36: 1 | EO36: 1 | FA36: 1 | FR36: 1 | HR36: 1 | IZ36: 1 | JI36: 1 | KC36: 1 | LS36: 1 | MP36: 1 | NZ36: 1 | PS36: 1 | QC36: 1 | RC36: 1 | RI36: 1 | SC36: 1 | SS36: 1 | SZ36: 1 | TN36: 1 | UW36: 1 | WI36: 1 | WP36: 1 | YP36: 1 | ABN36: 1 | ADB36: 1 | ADS36: 1 | ADX36: 1 | ADZ36: 1 | AEA36: 1 | AET36: 1 | AGP36: 1 | AHQ36: 1 | AIC36: 1 | AIH36: 1 | AJI36: 1 | AKT36: 1 | AMA36: 38
A37: Grand Total | B37: 1 | C37: 1 | D37: 1 | E37: 1 | F37: 1 | G37: 1 | H37: 1 | I37: 1 | J37: 1 | K37: 1 | L37: 1 | M37: 1 | N37: 1 | O37: 1 | P37: 1 | Q37: 1 | R37: 1 | S37: 1 | T37: 1 | U37: 1 | V37: 1 | W37: 1 | X37: 1 | Y37: 1 | Z37: 1 | AA37: 1 | AB37: 1 | AC37: 1 | AD37: 1 | AE37: 1 | AF37: 1 | AG37: 1 | AH37: 1 | AI37: 1 | AJ37: 1 | AK37: 1 | AL37: 1 | AM37: 1 | AN37: 1 | AO37: 1 | AP37: 1 | AQ37: 1 | AR37: 1 | AS37: 1 | AT37: 1 | AU37: 1 | AV37: 1 | AW37: 1 | AX37: 1 | AY37: 1 | AZ37: 1 | BA37: 1 | BB37: 1 | BC37: 1 | BD37: 1 | BE37: 1 | BF37: 1 | BG37: 1 | BH37: 1 | BI37: 1 | BJ37: 1 | BK37: 1 | BL37: 1 | BM37: 1 | BN37: 1 | BO37: 1 | BP37: 1 | BQ37: 1 | BR37: 1 | BS37: 1 | BT37: 1 | BU37: 1 | BV37: 1 | BW37: 1 | BX37: 1 | BY37: 1 | BZ37: 1 | CA37: 1 | CB37: 1 | CC37: 1 | CD37: 1 | CE37: 1 | CF37: 1 | CG37: 1 | CH37: 1 | CI37: 1 | CJ37: 1 | CK37: 1 | CL37: 1 | CM37: 1 | CN37: 1 | CO37: 1 | CP37: 1 | CQ37: 1 | CR37: 1 | CS37: 1 | CT37: 1 | CU37: 1 | CV37: 1 | CW37: 1 | CX37: 1 | CY37: 1 | CZ37: 1 | DA37: 1 | DB37: 1 | DC37: 1 | DD37: 1 | DE37: 1 | DF37: 1 | DG37: 1 | DH37: 1 | DI37: 1 | DJ37: 1 | DK37: 1 | DL37: 1 | DM37: 1 | DN37: 1 | DO37: 1 | DP37: 1 | DQ37: 1 | DR37: 1 | DS37: 1 | DT37: 1 | DU37: 1 | DV37: 1 | DW37: 1 | DX37: 1 | DY37: 1 | DZ37: 1 | EA37: 1 | EB37: 1 | EC37: 1 | ED37: 1 | EE37: 1 | EF37: 1 | EG37: 1 | EH37: 1 | EI37: 1 | EJ37: 1 | EK37: 1 | EL37: 1 | EM37: 1 | EN37: 1 | EO37: 1 | EP37: 1 | EQ37: 1 | ER37: 1 | ES37: 1 | ET37: 1 | EU37: 1 | EV37: 1 | EW37: 1 | EX37: 1 | EY37: 1 | EZ37: 1 | FA37: 1 | FB37: 1 | FC37: 1 | FD37: 1 | FE37: 1 | FF37: 1 | FG37: 1 | FH37: 1 | FI37: 1 | FJ37: 1 | FK37: 1 | FL37: 1 | FM37: 1 | FN37: 1 | FO37: 1 | FP37: 1 | FQ37: 1 | FR37: 1 | FS37: 1 | FT37: 1 | FU37: 1 | FV37: 1 | FW37: 1 | FX37: 1 | FY37: 1 | FZ37: 1 | GA37: 1 | GB37: 1 | GC37: 1 | GD37: 1 | GE37: 1 | GF37: 1 | GG37: 1 | GH37: 1 | GI37: 1 | GJ37: 1 | GK37: 1 | GL37: 1 | GM37: 1 | GN37: 1 | GO37: 1 | GP37: 1 | GQ37: 1 | GR37: 1 | GS37: 1 | GT37: 1 | GU37: 1 | GV37: 1 | GW37: 1 | GX37: 1 | GY37: 1 | GZ37: 1 | HA37: 1 | HB37: 1 | HC37: 1 | HD37: 1 | HE37: 1 | HF37: 1 | HG37: 1 | HH37: 1 | HI37: 1 | HJ37: 1 | HK37: 1 | HL37: 1 | HM37: 1 | HN37: 1 | HO37: 1 | HP37: 1 | HQ37: 1 | HR37: 1 | HS37: 1 | HT37: 1 | HU37: 1 | HV37: 1 | HW37: 1 | HX37: 1 | HY37: 1 | HZ37: 1 | IA37: 1 | IB37: 1 | IC37: 1 | ID37: 1 | IE37: 1 | IF37: 1 | IG37: 1 | IH37: 1 | II37: 1 | IJ37: 1 | IK37: 1 | IL37: 1 | IM37: 1 | IN37: 1 | IO37: 1 | IP37: 1 | IQ37: 1 | IR37: 1 | IS37: 1 | IT37: 1 | IU37: 1 | IV37: 1 | IW37: 1 | IX37: 1 | IY37: 1 | IZ37: 1 | JA37: 1 | JB37: 1 | JC37: 1 | JD37: 1 | JE37: 1 | JF37: 1 | JG37: 1 | JH37: 1 | JI37: 1 | JJ37: 1 | JK37: 1 | JL37: 1 | JM37: 1 | JN37: 1 | JO37: 1 | JP37: 1 | JQ37: 1 | JR37: 1 | JS37: 1 | JT37: 1 | JU37: 1 | JV37: 1 | JW37: 1 | JX37: 1 | JY37: 1 | JZ37: 1 | KA37: 1 | KB37: 1 | KC37: 1 | KD37: 1 | KE37: 1 | KF37: 1 | KG37: 1 | KH37: 1 | KI37: 1 | KJ37: 1 | KK37: 1 | KL37: 1 | KM37: 1 | KN37: 1 | KO37: 1 | KP37: 1 | KQ37: 1 | KR37: 1 | KS37: 1 | KT37: 1 | KU37: 1 | KV37: 1 | KW37: 1 | KX37: 1 | KY37: 1 | KZ37: 1 | LA37: 1 | LB37: 1 | LC37: 1 | LD37: 1 | LE37: 1 | LF37: 1 | LG37: 1 | LH37: 1 | LI37: 1 | LJ37: 1 | LK37: 1 | LL37: 1 | LM37: 1 | LN37: 1 | LO37: 1 | LP37: 1 | LQ37: 1 | LR37: 1 | LS37: 1 | LT37: 1 | LU37: 1 | LV37: 1 | LW37: 1 | LX37: 1 | LY37: 1 | LZ37: 1 | MA37: 1 | MB37: 1 | MC37: 1 | MD37: 1 | ME37: 1 | MF37: 1 | MG37: 1 | MH37: 1 | MI37: 1 | MJ37: 1 | MK37: 1 | ML37: 1 | MM37: 1 | MN37: 1 | MO37: 1 | MP37: 1 | MQ37: 1 | MR37: 1 | MS37: 1 | MT37: 1 | MU37: 1 | MV37: 1 | MW37: 1 | MX37: 1 | MY37: 1 | MZ37: 1 | NA37: 1 | NB37: 1 | NC37: 1 | ND37: 1 | NE37: 1 | NF37: 1 | NG37: 1 | NH37: 1 | NI37: 1 | NJ37: 1 | NK37: 1 | NL37: 1 | NM37: 1 | NN37: 1 | NO37: 1 | NP37: 1 | NQ37: 1 | NR37: 1 | NS37: 1 | NT37: 1 | NU37: 1 | NV37: 1 | NW37: 1 | NX37: 1 | NY37: 1 | NZ37: 1 | OA37: 1 | OB37: 1 | OC37: 1 | OD37: 1 | OE37: 1 | OF37: 1 | OG37: 1 | OH37: 1 | OI37: 1 | OJ37: 1 | OK37: 1 | OL37: 1 | OM37: 1 | ON37: 1 | OO37: 1 | OP37: 1 | OQ37: 1 | OR37: 1 | OS37: 1 | OT37: 1 | OU37: 1 | OV37: 1 | OW37: 1 | OX37: 1 | OY37: 1 | OZ37: 1 | PA37: 1 | PB37: 1 | PC37: 1 | PD37: 1 | PE37: 1 | PF37: 1 | PG37: 1 | PH37: 1 | PI37: 1 | PJ37: 1 | PK37: 1 | PL37: 1 | PM37: 1 | PN37: 1 | PO37: 1 | PP37: 1 | PQ37: 1 | PR37: 1 | PS37: 1 | PT37: 1 | PU37: 1 | PV37: 1 | PW37: 1 | PX37: 1 | PY37: 1 | PZ37: 1 | QA37: 1 | QB37: 1 | QC37: 1 | QD37: 1 | QE37: 1 | QF37: 1 | QG37: 1 | QH37: 1 | QI37: 1 | QJ37: 1 | QK37: 1 | QL37: 1 | QM37: 1 | QN37: 1 | QO37: 1 | QP37: 1 | QQ37: 1 | QR37: 1 | QS37: 1 | QT37: 1 | QU37: 1 | QV37: 1 | QW37: 1 | QX37: 1 | QY37: 1 | QZ37: 1 | RA37: 1 | RB37: 1 | RC37: 1 | RD37: 1 | RE37: 1 | RF37: 1 | RG37: 1 | RH37: 1 | RI37: 1 | RJ37: 1 | RK37: 1 | RL37: 1 | RM37: 1 | RN37: 1 | RO37: 1 | RP37: 1 | RQ37: 1 | RR37: 1 | RS37: 1 | RT37: 1 | RU37: 1 | RV37: 1 | RW37: 1 | RX37: 1 | RY37: 1 | RZ37: 1 | SA37: 1 | SB37: 1 | SC37: 1 | SD37: 1 | SE37: 1 | SF37: 1 | SG37: 1 | SH37: 1 | SI37: 1 | SJ37: 1 | SK37: 1 | SL37: 1 | SM37: 1 | SN37: 1 | SO37: 1 | SP37: 1 | SQ37: 1 | SR37: 1 | SS37: 1 | ST37: 1 | SU37: 1 | SV37: 1 | SW37: 1 | SX37: 1 | SY37: 1 | SZ37: 1 | TA37: 1 | TB37: 1 | TC37: 1 | TD37: 1 | TE37: 1 | TF37: 1 | TG37: 1 | TH37: 1 | TI37: 1 | TJ37: 1 | TK37: 1 | TL37: 1 | TM37: 1 | TN37: 1 | TO37: 1 | TP37: 1 | TQ37: 1 | TR37: 1 | TS37: 1 | TT37: 1 | TU37: 1 | TV37: 1 | TW37: 1 | TX37: 1 | TY37: 1 | TZ37: 1 | UA37: 1 | UB37: 1 | UC37: 1 | UD37: 1 | UE37: 1 | UF37: 1 | UG37: 1 | UH37: 1 | UI37: 1 | UJ37: 1 | UK37: 1 | UL37: 1 | UM37: 1 | UN37: 1 | UO37: 1 | UP37: 1 | UQ37: 1 | UR37: 1 | US37: 1 | UT37: 1 | UU37: 1 | UV37: 1 | UW37: 1 | UX37: 1 | UY37: 1 | UZ37: 1 | VA37: 1 | VB37: 1 | VC37: 1 | VD37: 1 | VE37: 1 | VF37: 1 | VG37: 1 | VH37: 1 | VI37: 1 | VJ37: 1 | VK37: 1 | VL37: 1 | VM37: 1 | VN37: 1 | VO37: 1 | VP37: 1 | VQ37: 1 | VR37: 1 | VS37: 1 | VT37: 1 | VU37: 1 | VV37: 1 | VW37: 1 | VX37: 1 | VY37: 1 | VZ37: 1 | WA37: 1 | WB37: 1 | WC37: 1 | WD37: 1 | WE37: 1 | WF37: 1 | WG37: 1 | WH37: 1 | WI37: 1 | WJ37: 1 | WK37: 1 | WL37: 1 | WM37: 1 | WN37: 1 | WO37: 1 | WP37: 1 | WQ37: 1 | WR37: 1 | WS37: 1 | WT37: 1 | WU37: 1 | WV37: 1 | WW37: 1 | WX37: 1 | WY37: 1 | WZ37: 1 | XA37: 1 | XB37: 1 | XC37: 1 | XD37: 1 | XE37: 1 | XF37: 1 | XG37: 1 | XH37: 1 | XI37: 1 | XJ37: 1 | XK37: 1 | XL37: 1 | XM37: 1 | XN37: 1 | XO37: 1 | XP37: 1 | XQ37: 1 | XR37: 1 | XS37: 1 | XT37: 1 | XU37: 1 | XV37: 1 | XW37: 1 | XX37: 1 | XY37: 1 | XZ37: 1 | YA37: 1 | YB37: 1 | YC37: 1 | YD37: 1 | YE37: 1 | YF37: 1 | YG37: 1 | YH37: 1 | YI37: 1 | YJ37: 1 | YK37: 1 | YL37: 1 | YM37: 1 | YN37: 1 | YO37: 1 | YP37: 1 | YQ37: 1 | YR37: 1 | YS37: 1 | YT37: 1 | YU37: 1 | YV37: 1 | YW37: 1 | YX37: 1 | YY37: 1 | YZ37: 1 | ZA37: 1 | ZB37: 1 | ZC37: 1 | ZD37: 1 | ZE37: 1 | ZF37: 1 | ZG37: 1 | ZH37: 1 | ZI37: 1 | ZJ37: 1 | ZK37: 1 | ZL37: 1 | ZM37: 1 | ZN37: 1 | ZO37: 1 | ZP37: 1 | ZQ37: 1 | ZR37: 1 | ZS37: 1 | ZT37: 1 | ZU37: 1 | ZV37: 1 | ZW37: 1 | ZX37: 1 | ZY37: 1 | ZZ37: 1 | AAA37: 1 | AAB37: 1 | AAC37: 1 | AAD37: 1 | AAE37: 1 | AAF37: 1 | AAG37: 1 | AAH37: 1 | AAI37: 1 | AAJ37: 1 | AAK37: 1 | AAL37: 1 | AAM37: 1 | AAN37: 1 | AAO37: 1 | AAP37: 1 | AAQ37: 1 | AAR37: 1 | AAS37: 1 | AAT37: 1 | AAU37: 1 | AAV37: 1 | AAW37: 1 | AAX37: 1 | AAY37: 1 | AAZ37: 1 | ABA37: 1 | ABB37: 1 | ABC37: 1 | ABD37: 1 | ABE37: 1 | ABF37: 1 | ABG37: 1 | ABH37: 1 | ABI37: 1 | ABJ37: 1 | ABK37: 1 | ABL37: 1 | ABM37: 1 | ABN37: 1 | ABO37: 1 | ABP37: 1 | ABQ37: 1 | ABR37: 1 | ABS37: 1 | ABT37: 1 | ABU37: 1 | ABV37: 1 | ABW37: 1 | ABX37: 1 | ABY37: 1 | ABZ37: 1 | ACA37: 1 | ACB37: 1 | ACC37: 1 | ACD37: 1 | ACE37: 1 | ACF37: 1 | ACG37: 1 | ACH37: 1 | ACI37: 1 | ACJ37: 1 | ACK37: 1 | ACL37: 1 | ACM37: 1 | ACN37: 1 | ACO37: 1 | ACP37: 1 | ACQ37: 1 | ACR37: 1 | ACS37: 1 | ACT37: 1 | ACU37: 1 | ACV37: 1 | ACW37: 1 | ACX37: 1 | ACY37: 1 | ACZ37: 1 | ADA37: 1 | ADB37: 1 | ADC37: 1 | ADD37: 1 | ADE37: 1 | ADF37: 1 | ADG37: 1 | ADH37: 1 | ADI37: 1 | ADJ37: 1 | ADK37: 1 | ADL37: 1 | ADM37: 1 | ADN37: 1 | ADO37: 1 | ADP37: 1 | ADQ37: 1 | ADR37: 1 | ADS37: 1 | ADT37: 1 | ADU37: 1 | ADV37: 1 | ADW37: 1 | ADX37: 1 | ADY37: 1 | ADZ37: 1 | AEA37: 1 | AEB37: 1 | AEC37: 1 | AED37: 1 | AEE37: 1 | AEF37: 1 | AEG37: 1 | AEH37: 1 | AEI37: 1 | AEJ37: 1 | AEK37: 1 | AEL37: 1 | AEM37: 1 | AEN37: 1 | AEO37: 1 | AEP37: 1 | AEQ37: 1 | AER37: 1 | AES37: 1 | AET37: 1 | AEU37: 1 | AEV37: 1 | AEW37: 1 | AEX37: 1 | AEY37: 1 | AEZ37: 1 | AFA37: 1 | AFB37: 1 | AFC37: 1 | AFD37: 1 | AFE37: 1 | AFF37: 1 | AFG37: 1 | AFH37: 1 | AFI37: 1 | AFJ37: 1 | AFK37: 1 | AFL37: 1 | AFM37: 1 | AFN37: 1 | AFO37: 1 | AFP37: 1 | AFQ37: 1 | AFR37: 1 | AFS37: 1 | AFT37: 1 | AFU37: 1 | AFV37: 1 | AFW37: 1 | AFX37: 1 | AFY37: 1 | AFZ37: 1 | AGA37: 1 | AGB37: 1 | AGC37: 1 | AGD37: 1 | AGE37: 1 | AGF37: 1 | AGG37: 1 | AGH37: 1 | AGI37: 1 | AGJ37: 1 | AGK37: 1 | AGL37: 1 | AGM37: 1 | AGN37: 1 | AGO37: 1 | AGP37: 1 | AGQ37: 1 | AGR37: 1 | AGS37: 1 | AGT37: 1 | AGU37: 1 | AGV37: 1 | AGW37: 1 | AGX37: 1 | AGY37: 1 | AGZ37: 1 | AHA37: 1 | AHB37: 1 | AHC37: 1 | AHD37: 1 | AHE37: 1 | AHF37: 1 | AHG37: 1 | AHH37: 1 | AHI37: 1 | AHJ37: 1 | AHK37: 1 | AHL37: 1 | AHM37: 1 | AHN37: 1 | AHO37: 1 | AHP37: 1 | AHQ37: 1 | AHR37: 1 | AHS37: 1 | AHT37: 1 | AHU37: 1 | AHV37: 1 | AHW37: 1 | AHX37: 1 | AHY37: 1 | AHZ37: 1 | AIA37: 1 | AIB37: 1 | AIC37: 1 | AID37: 1 | AIE37: 1 | AIF37: 1 | AIG37: 1 | AIH37: 1 | AII37: 1 | AIJ37: 1 | AIK37: 1 | AIL37: 1 | AIM37: 1 | AIN37: 1 | AIO37: 1 | AIP37: 1 | AIQ37: 1 | AIR37: 1 | AIS37: 1 | AIT37: 1 | AIU37: 1 | AIV37: 1 | AIW37: 1 | AIX37: 1 | AIY37: 1 | AIZ37: 1 | AJA37: 1 | AJB37: 1 | AJC37: 1 | AJD37: 1 | AJE37: 1 | AJF37: 1 | AJG37: 1 | AJH37: 1 | AJI37: 1 | AJJ37: 1 | AJK37: 1 | AJL37: 1 | AJM37: 1 | AJN37: 1 | AJO37: 1 | AJP37: 1 | AJQ37: 1 | AJR37: 1 | AJS37: 1 | AJT37: 1 | AJU37: 1 | AJV37: 1 | AJW37: 1 | AJX37: 1 | AJY37: 1 | AJZ37: 1 | AKA37: 1 | AKB37: 1 | AKC37: 1 | AKD37: 1 | AKE37: 1 | AKF37: 1 | AKG37: 1 | AKH37: 1 | AKI37: 1 | AKJ37: 1 | AKK37: 1 | AKL37: 1 | AKM37: 1 | AKN37: 1 | AKO37: 1 | AKP37: 1 | AKQ37: 1 | AKR37: 1 | AKS37: 1 | AKT37: 1 | AKU37: 1 | AKV37: 1 | AKW37: 1 | AKX37: 1 | AKY37: 1 | AKZ37: 1 | ALA37: 1 | ALB37: 1 | ALC37: 1 | ALD37: 1 | ALE37: 1 | ALF37: 1 | ALG37: 1 | ALH37: 1 | ALI37: 1 | ALJ37: 1 | ALK37: 1 | ALL37: 1 | ALM37: 1 | ALN37: 1 | ALO37: 1 | ALP37: 1 | ALQ37: 1 | ALR37: 1 | ALS37: 1 | ALT37: 1 | ALU37: 1 | ALV37: 1 | ALW37: 1 | ALX37: 1 | ALY37: 1 | ALZ37: 1 | AMA37: 1013

Sheet Cleaned_Data
A1: pick_id | B1: order_id | C1: picker_id | D1: zone_id | E1: item_id | F1: start_time | G1: finish_time | H1: quantity | I1: pick_time_min | J1: missing_timestamp | K1: negative_duration | L1: invalid_quantity | M1: item_count | N1: priority | O1: order_timestamp | P1: item_count_missing | Q1: category | R1: size | S1: storage_class | T1: shift | U1: experience_band | V1: zone_type | W1: distance_band | X1: order_hour | Y1: order_day | Z1: order_size_group | AA1: pick_time_per_unit
A2: P000440 | B2: O00104 | C2: W012 | D2: G | E2: I0075 | F2: 46294.219 | G2: 46294.231 | H2: 3 | I2: 18 | J2: FALSE | K2: FALSE | L2: FALSE | M2: 15 | N2: Normal | O2: 46294.217 | P2: FALSE | Q2: Fragile Goods | R2: Small | S2: Standard | T2: Night | U2: Beginner | V2: Cold Storage | W2: Far | X2: 5 | Y2: Tuesday | Z2: Large (11-20) | AA2: 6
A3: P000293 | B3: O00069 | C3: W008 | D3: G | E3: I0011 | F3: 46285.774 | G3: 46285.786 | H3: 5 | I3: 17 | J3: FALSE | K3: FALSE | L3: FALSE | M3: 6 | N3: High | O3: 46285.751 | P3: FALSE | Q3: Fragile Goods | R3: Medium | S3: Climate-Controlled | T3: Night | U3: Beginner | V3: Cold Storage | W3: Far | X3: 18 | Y3: Sunday | Z3: Medium (6-10) | AA3: 3.4
A4: P000837 | B4: O00196 | C4: W032 | D4: B | E4: I0045 | F4: 46269.697 | G4: 46269.708 | H4: 6 | I4: 17 | J4: FALSE | K4: FALSE | L4: FALSE | M4: 15 | N4: Normal | O4: 46269.66 | P4: FALSE | Q4: Apparel | R4: Large | S4: Climate-Controlled | T4: Evening | U4: Beginner | V4: Bulk Storage | W4: Far | X4: 15 | Y4: Friday | Z4: Large (11-20) | AA4: 2.8333333
A5: P000426 | B5: O00101 | C5: W006 | D5: G | E5: I0036 | F5: 46289.231 | G5: 46289.242 | H5: 6 | I5: 16 | J5: FALSE | K5: FALSE | L5: FALSE | M5: 3 | N5: High | O5: 46289.171 | P5: FALSE | Q5: Apparel | R5: Small | S5: Unknown | T5: Night | U5: Beginner | V5: Cold Storage | W5: Far | X5: 4 | Y5: Thursday | Z5: Small (1-5) | AA5: 2.6666667
A6: P000880 | B6: O00204 | C6: W032 | D6: D | E6: I0049 | F6: 46275.089 | G6: 46275.1 | H6: 1 | I6: 16 | J6: FALSE | K6: FALSE | L6: FALSE | M6: 10 | N6: Normal | O6: 46275.055 | P6: FALSE | Q6: Small Parts | R6: Medium | S6: Standard | T6: Evening | U6: Beginner | V6: Fragile | W6: Unknown | X6: 1 | Y6: Thursday | Z6: Medium (6-10) | AA6: 16
A7: P000016 | B7: O00007 | C7: W006 | D7: G | E7: I0059 | F7: 46280.345 | G7: 46280.356 | H7: 5 | I7: 16 | J7: FALSE | K7: FALSE | L7: FALSE | M7: 10 | N7: Urgent | O7: 46280.223 | P7: FALSE | Q7: Electronics | R7: Medium | S7: Bulk | T7: Night | U7: Beginner | V7: Cold Storage | W7: Far | X7: 5 | Y7: Tuesday | Z7: Medium (6-10) | AA7: 3.2
A8: P000685 | B8: O00161 | C8: W015 | D8: G | E8: I0005 | F8: 46282.884 | G8: 46282.894 | H8: 7 | I8: 15 | J8: FALSE | K8: FALSE | L8: FALSE | M8: 5 | N8: Normal | O8: 46282.871 | P8: FALSE | Q8: Apparel | R8: Small | S8: Climate-Controlled | T8: Night | U8: Unknown | V8: Cold Storage | W8: Far | X8: 20 | Y8: Thursday | Z8: Small (1-5) | AA8: 2.1428571
A9: P000216 | B9: O00048 | C9: W023 | D9: D | E9: I0011 | F9: 46274.592 | G9: 46274.603 | H9: 5 | I9: 15 | J9: FALSE | K9: FALSE | L9: FALSE | M9: 10 | N9: Urgent | O9: 46274.532 | P9: FALSE | Q9: Fragile Goods | R9: Medium | S9: Climate-Controlled | T9: Unknown | U9: Beginner | V9: Fragile | W9: Unknown | X9: 12 | Y9: Wednesday | Z9: Medium (6-10) | AA9: 3
A10: P001006 | B10: O00232 | C10: W008 | D10: B | E10: I0055 | F10: 46268.008 | G10: 46268.019 | H10: 6 | I10: 15 | J10: FALSE | K10: FALSE | L10: FALSE | M10: 15 | N10: High | O10: 46267.896 | P10: FALSE | Q10: Fragile Goods | R10: Medium | S10: Climate-Controlled | T10: Night | U10: Beginner | V10: Bulk Storage | W10: Far | X10: 21 | Y10: Wednesday | Z10: Large (11-20) | AA10: 2.5
A11: P000581 | B11: O00136 | C11: W006 | D11: G | E11: I0039 | F11: 46266.606 | G11: 46266.617 | H11: 2 | I11: 15 | J11: FALSE | K11: FALSE | L11: FALSE | M11: 12 | N11: High | O11: 46266.548 | P11: FALSE | Q11: Apparel | R11: Small | S11: Fragile | T11: Night | U11: Beginner | V11: Cold Storage | W11: Far | X11: 13 | Y11: Tuesday | Z11: Large (11-20) | AA11: 7.5
A12: P000949 | B12: O00219 | C12: W008 | D12: D | E12: I0050 | F12: 46273.536 | G12: 46273.547 | H12: 7 | I12: 15 | J12: FALSE | K12: FALSE | L12: FALSE | M12: 10 | N12: Low | O12: 46273.465 | P12: FALSE | Q12: Home Goods | R12: Medium | S12: Bulk | T12: Night | U12: Beginner | V12: Fragile | W12: Unknown | X12: 11 | Y12: Tuesday | Z12: Medium (6-10) | AA12: 2.1428571
A13: P000166 | B13: O00039 | C13: W021 | D13: G | E13: I0010 | F13: 46277.045 | G13: 46277.056 | H13: 7 | I13: 15 | J13: FALSE | K13: FALSE | L13: FALSE | M13: 20 | N13: Normal | O13: 46277.038 | P13: FALSE | Q13: Fragile Goods | R13: Medium | S13: Standard | T13: Night | U13: Intermediate | V13: Cold Storage | W13: Far | X13: 0 | Y13: Saturday | Z13: Large (11-20) | AA13: 2.1428571
... A32: P000461 | B32: O00108 | C32: W008 | D32: G | E32: I0010 | F32: 46269.497 | G32: 46269.506 | H32: 3 | I32: 13 | J32: FALSE | K32: FALSE | L32: FALSE | M32: 10 | N32: Urgent | O32: 46269.49 | P32: FALSE | Q32: Fragile Goods | R32: Medium | S32: Standard | T32: Night | U32: Beginner | V32: Cold Storage | W32: Far | X32: 11 | Y32: Friday | Z32: Medium (6-10) | AA32: 4.3333333
A33: P000208 | B33: O00047 | C33: W023 | D33: G | E33: I0017 | F33: 46266.908 | G33: 46266.917 | H33: 5 | I33: 13 | J33: FALSE | K33: FALSE | L33: FALSE | N33: High | O33: 46266.843 | P33: TRUE | Q33: Bulk Materials | R33: Medium | S33: Bulk | T33: Unknown | U33: Beginner | V33: Cold Storage | W33: Far | X33: 20 | Y33: Tuesday | AA33: 2.6
A34: P000632 | B34: O00146 | C34: W022 | D34: D | E34: I0078 | F34: 46269.579 | G34: 46269.588 | H34: 5 | I34: 13 | J34: FALSE | K34: FALSE | L34: FALSE | M34: 12 | N34: Normal | O34: 46269.522 | P34: FALSE | Q34: Apparel | R34: Medium | S34: Climate-Controlled | T34: Unknown | U34: Intermediate | V34: Fragile | W34: Unknown | X34: 12 | Y34: Friday | Z34: Large (11-20) | AA34: 2.6
A35: P000253 | B35: O00059 | C35: W032 | D35: G | E35: I0033 | F35: 46286.875 | G35: 46286.884 | H35: 2 | I35: 13 | J35: FALSE | K35: FALSE | L35: FALSE | M35: 10 | N35: High | O35: 46286.793 | P35: FALSE | Q35: Small Parts | R35: Medium | S35: Bulk | T35: Evening | U35: Beginner | V35: Cold Storage | W35: Far | X35: 19 | Y35: Monday | Z35: Medium (6-10) | AA35: 6.5
A36: P000032 | B36: O00011 | C36: W008 | D36: B | E36: I0027 | F36: 46284.569 | G36: 46284.578 | H36: 5 | I36: 13 | J36: FALSE | K36: FALSE | L36: FALSE | M36: 15 | N36: Low | O36: 46284.526 | P36: FALSE | Q36: Unknown | R36: Large | S36: Bulk | T36: Night | U36: Beginner | V36: Bulk Storage | W36: Far | X36: 12 | Y36: Saturday | Z36: Large (11-20) | AA36: 2.6
A37: P000295 | B37: O00069 | C37: W030 | D37: D | E37: I0065 | F37: 46285.809 | G37: 46285.818 | H37: 4 | I37: 13 | J37: FALSE | K37: FALSE | L37: FALSE | M37: 6 | N37: High | O37: 46285.751 | P37: FALSE | Q37: Small Parts | R37: Medium | S37: Fragile | T37: Night | U37: Unknown | V37: Fragile | W37: Unknown | X37: 18 | Y37: Sunday | Z37: Medium (6-10) | AA37: 3.25
A38: P000672 | B38: O00159 | C38: W014 | D38: D | E38: I0037 | F38: 46292.595 | G38: 46292.604 | H38: 6 | I38: 13 | J38: FALSE | K38: FALSE | L38: FALSE | M38: 10 | N38: High | O38: 46292.531 | P38: FALSE | Q38: Electronics | R38: Medium | S38: Climate-Controlled | T38: Morning | U38: Unknown | V38: Fragile | W38: Unknown | X38: 12 | Y38: Sunday | Z38: Medium (6-10) | AA38: 2.1666667
A39: P000003 | B39: O00002 | C39: W032 | D39: B | E39: I0019 | F39: 46270.409 | G39: 46270.418 | H39: 4 | I39: 13 | J39: FALSE | K39: FALSE | L39: FALSE | M39: 5 | N39: Normal | O39: 46270.368 | P39: FALSE | Q39: Fragile Goods | R39: Medium | S39: Bulk | T39: Evening | U39: Beginner | V39: Bulk Storage | W39: Far | X39: 8 | Y39: Saturday | Z39: Small (1-5) | AA39: 3.25
A40: P001127 | B40: O00258 | C40: W023 | D40: G | E40: I0025 | F40: 46271.129 | G40: 46271.138 | H40: 4 | I40: 13 | J40: FALSE | K40: FALSE | L40: FALSE | M40: 5 | N40: Low | O40: 46271.107 | P40: FALSE | Q40: Home Goods | R40: Small | S40: Fragile | T40: Unknown | U40: Beginner | V40: Cold Storage | W40: Far | X40: 2 | Y40: Sunday | Z40: Small (1-5) | AA40: 3.25
A41: P000353 | B41: O00081 | C41: W008 | D41: D | E41: I0022 | F41: 46283.751 | G41: 46283.76 | H41: 6 | I41: 13 | J41: FALSE | K41: FALSE | L41: FALSE | M41: 20 | N41: Low | O41: 46283.735 | P41: FALSE | Q41: Unknown | R41: Small | S41: Standard | T41: Night | U41: Beginner | V41: Fragile | W41: Unknown | X41: 17 | Y41: Friday | Z41: Large (11-20) | AA41: 2.1666667
A42: P000753 | B42: O00178 | C42: W012 | D42: B | E42: I0029 | F42: 46273.496 | G42: 46273.505 | H42: 4 | I42: 13 | J42: FALSE | K42: FALSE | L42: FALSE | M42: 8 | N42: Normal | O42: 46273.438 | P42: FALSE | Q42: Small Parts | R42: Medium | S42: Standard | T42: Night | U42: Beginner | V42: Bulk Storage | W42: Far | X42: 10 | Y42: Tuesday | Z42: Medium (6-10) | AA42: 3.25
A43: P001109 | B43: O00250 | C43: W012 | D43: D | E43: I0024 | F43: 46274.09 | G43: 46274.099 | H43: 5 | I43: 13 | J43: FALSE | K43: FALSE | L43: FALSE | M43: 6 | N43: Low | O43: 46274.065 | P43: FALSE | Q43: Fragile Goods | R43: Small | S43: Fragile | T43: Night | U43: Beginner | V43: Fragile | W43: Unknown | X43: 1 | Y43: Wednesday | Z43: Medium (6-10) | AA43: 2.6
A44: P001110 | B44: O00251 | C44: W019 | D44: G | E44: I0002 | F44: 46274.794 | G44: 46274.803 | H44: 7 | I44: 13 | J44: FALSE | K44: FALSE | L44: FALSE | M44: 10 | N44: High | O44: 46274.694 | P44: FALSE | Q44: Small Parts | R44: Small | S44: Fragile | T44: Night | U44: Intermediate | V44: Cold Storage | W44: Far | X44: 16 | Y44: Wednesday | Z44: Medium (6-10) | AA44: 1.8571429
A45: P000421 | B45: O00098 | C45: W015 | D45: G | E45: I0040 | F45: 46277.129 | G45: 46277.138 | H45: 5 | I45: 13 | J45: FALSE | K45: FALSE | L45: FALSE | M45: 5 | N45: High | O45: 46277.106 | P45: FALSE | Q45: Unknown | R45: Medium | S45: Standard | T45: Night | U45: Unknown | V45: Cold Storage | W45: Far | X45: 2 | Y45: Saturday | Z45: Small (1-5) | AA45: 2.6
... A49: P000373 | B49: O00085 | C49: W021 | D49: G | E49: I0034 | F49: 46270.81 | G49: 46270.819 | H49: 4 | I49: 13 | J49: FALSE | K49: FALSE | L49: FALSE | M49: 4 | N49: Normal | O49: 46270.777 | P49: FALSE | Q49: Bulk Materials | R49: Small | S49: Climate-Controlled | T49: Night | U49: Intermediate | V49: Cold Storage | W49: Far | X49: 18 | Y49: Saturday | Z49: Small (1-5) | AA49: 3.25
A50: P000177 | B50: O00041 | C50: W032 | D50: B | E50: I0007 | F50: 46281.95 | G50: 46281.959 | H50: 4 | I50: 13 | J50: FALSE | K50: FALSE | L50: FALSE | M50: 12 | N50: High | P50: FALSE | Q50: Small Parts | R50: Medium | S50: Fragile | T50: Evening | U50: Beginner | V50: Bulk Storage | W50: Far | Z50: Large (11-20) | AA50: 3.25
A51: P000122 | B51: O00029 | C51: W007 | D51: G | E51: I0068 | F51: 46273.143 | G51: 46273.152 | H51: 4 | I51: 13 | J51: FALSE | K51: FALSE | L51: FALSE | M51: 6 | N51: Normal | O51: 46273.138 | P51: FALSE | Q51: Electronics | R51: Medium | S51: Climate-Controlled | T51: Night | U51: Intermediate | V51: Cold Storage | W51: Far | X51: 3 | Y51: Tuesday | Z51: Medium (6-10) | AA51: 3.25
A52: P000504 | B52: O00120 | C52: W006 | D52: D | E52: I0043 | F52: 46273.392 | G52: 46273.401 | H52: 6 | I52: 13 | J52: FALSE | K52: FALSE | L52: FALSE | M52: 3 | N52: Normal | O52: 46273.313 | P52: FALSE | Q52: Small Parts | R52: Small | S52: Fragile | T52: Night | U52: Beginner | V52: Fragile | W52: Unknown | X52: 7 | Y52: Tuesday | Z52: Small (1-5) | AA52: 2.1666667
A53: P001007 | B53: O00232 | C53: W008 | D53: C | E53: I0045 | F53: 46267.925 | G53: 46267.934 | H53: 7 | I53: 13 | J53: FALSE | K53: FALSE | L53: FALSE | M53: 15 | N53: High | O53: 46267.896 | P53: FALSE | Q53: Apparel | R53: Large | S53: Climate-Controlled | T53: Night | U53: Beginner | V53: Small Parts | W53: Medium | X53: 21 | Y53: Wednesday | Z53: Large (11-20) | AA53: 1.8571429
A54: P000108 | B54: O00027 | C54: W012 | D54: G | E54: I0047 | F54: 46292.838 | G54: 46292.847 | H54: 6 | I54: 13 | J54: FALSE | K54: FALSE | L54: FALSE | M54: 12 | N54: High | O54: 46292.831 | P54: FALSE | Q54: Electronics | R54: Small | S54: Unknown | T54: Night | U54: Beginner | V54: Cold Storage | W54: Far | X54: 19 | Y54: Sunday | Z54: Large (11-20) | AA54: 2.1666667
A55: P000639 | B55: O00148 | C55: W020 | D55: G | E55: I0033 | F55: 46273.825 | G55: 46273.834 | H55: 6 | I55: 13 | J55: FALSE | K55: FALSE | L55: FALSE | M55: 5 | N55: Normal | O55: 46273.793 | P55: FALSE | Q55: Small Parts | R55: Medium | S55: Bulk | T55: Night | U55: Intermediate | V55: Cold Storage | W55: Far | X55: 19 | Y55: Tuesday | Z55: Small (1-5) | AA55: 2.1666667
A56: P000710 | B56: O00165 | C56: W006 | D56: G | E56: I0010 | F56: 46273.044 | G56: 46273.053 | H56: 1 | I56: 13 | J56: FALSE | K56: FALSE | L56: FALSE | M56: 10 | N56: Low | O56: 46273.044 | P56: FALSE | Q56: Fragile Goods | R56: Medium | S56: Standard | T56: Night | U56: Beginner | V56: Cold Storage | W56: Far | X56: 1 | Y56: Tuesday | Z56: Medium (6-10) | AA56: 13
A57: P000093 | B57: O00025 | C57: W003 | D57: D | E57: I0001 | F57: 46286.19 | G57: 46286.198 | H57: 6 | I57: 12 | J57: FALSE | K57: FALSE | L57: FALSE | M57: 20 | N57: Urgent | O57: 46286.135 | P57: FALSE | Q57: Fragile Goods | R57: Small | S57: Standard | T57: Night | U57: Intermediate | V57: Fragile | W57: Unknown | X57: 3 | Y57: Monday | Z57: Large (11-20) | AA57: 2
A58: P000712 | B58: O00166 | C58: W031 | D58: D | E58: I0016 | F58: 46285.547 | G58: 46285.555 | H58: 6 | I58: 12 | J58: FALSE | K58: FALSE | L58: FALSE | M58: 3 | N58: Low | O58: 46285.452 | P58: FALSE | Q58: Unknown | R58: Small | S58: Bulk | T58: Unknown | U58: Experienced | V58: Fragile | W58: Unknown | X58: 10 | Y58: Sunday | Z58: Small (1-5) | AA58: 2
A59: P000792 | B59: O00187 | C59: W004 | D59: G | E59: I0023 | F59: 46293.276 | G59: 46293.284 | H59: 7 | I59: 12 | J59: FALSE | K59: FALSE | L59: FALSE | M59: 3 | N59: Low | O59: 46293.162 | P59: FALSE | Q59: Home Goods | R59: Medium | S59: Bulk | T59: Evening | U59: Unknown | V59: Cold Storage | W59: Far | X59: 3 | Y59: Monday | Z59: Small (1-5) | AA59: 1.7142857
A60: P000604 | B60: O00139 | C60: W026 | D60: G | E60: I0043 | F60: 46288.845 | G60: 46288.853 | H60: 5 | I60: 12 | J60: FALSE | K60: FALSE | L60: FALSE | M60: 10 | N60: Normal | O60: 46288.808 | P60: FALSE | Q60: Small Parts | R60: Small | S60: Fragile | T60: Night | U60: Unknown | V60: Cold Storage | W60: Far | X60: 19 | Y60: Wednesday | Z60: Medium (6-10) | AA60: 2.4
A61: P000602 | B61: O00139 | C61: W027 | D61: D | E61: I0029 | F61: 46288.808 | G61: 46288.817 | H61: 3 | I61: 12 | J61: FALSE | K61: FALSE | L61: FALSE | M61: 10 | N61: Normal | O61: 46288.808 | P61: FALSE | Q61: Small Parts | R61: Medium | S61: Standard | T61: Morning | U61: Beginner | V61: Fragile | W61: Unknown | X61: 19 | Y61: Wednesday | Z61: Medium (6-10) | AA61: 4
...

Sheet Formula_Analysis
A1: Metric | B1: Result | C1: Interpretation
A2: Total pick records | B2: =COUNTA(Cleaned_Data!A:A)-1 -> 1013 | C2: Count of pick-level records
A3: Average picking time (minutes) | B3: =AVERAGE(Cleaned_Data!I:I) -> 7.7769003 | C3: Mean time per pick record
A4: Median picking time (minutes) | B4: =MEDIAN(Cleaned_Data!I:I) -> 8 | C4: Middle value of pick time
A5: Minimum picking time (minutes) | B5: =MIN(Cleaned_Data!I:I) -> 0 | C5: Shortest recorded pick duration
A6: Maximum picking time (minutes) | B6: =MAX(Cleaned_Data!I:I) -> 18 | C6: Longest recorded pick duration
A7: Total quantity picked | B7: =SUM(Cleaned_Data!H:H) -> 3926 | C7: Total quantity across pick records
A8: Average quantity per pick | B8: =AVERAGE(Cleaned_Data!H:H) -> 3.875617 | C8: Average quantity per record
A9: Standard deviation of pick time | B9: =_xlfn.SINGLE(_xlfn.STDEV.S(Cleaned_Data!I:I)) -> 2.8104793 | C9: Variation in pick duration
A10: Picks taking over 10 minutes | B10: =COUNTIF(Cleaned_Data!I:I,">10") -> 174 | C10: Count above the 10-minute threshold
A11: Percentage of picks over 10 minutes | B11: =IFERROR(B10/B2,0) -> 0.17176703 | C11: Share of records above 10 minutes
A12: Records with missing item count | B12: =COUNTBLANK(Cleaned_Data!M2:M1014) -> 32 | C12: Blank item_count cells in the exported dataset
A13: Records with Unknown shift | B13: =COUNTIF(Cleaned_Data!T:T,"Unknown") -> 157 | C13: Records with unavailable shift label
A14: Records with Unknown experience | B14: =COUNTIF(Cleaned_Data!U:U,"Unknown") -> 233 | C14: Records with unavailable experience label

Sheet Overall_Summary
A1: Metric | B1: Value
A2: Total merged pick records | B2: 1013
A3: Valid pick records | B3: 1013
A4: Unique orders | B4: 252
A5: Unique pickers | B5: 32
A6: Unique zones | B6: 8
A7: Average pick time (minutes) | B7: 7.78
A8: Median pick time (minutes) | B8: 8
A9: Average quantity per pick | B9: 3.88
A10: Average pick time per unit (minutes) | B10: 2.76

Sheet Zone_Analysis
A1: zone_id | B1: zone_type | C1: Pick_Records | D1: Avg_Pick_Min | E1: Median_Pick_Min | F1: Avg_Quantity
A2: A | B2: Fast-Moving | C2: 131 | D2: 5.18 | E2: 5 | F2: 3.82
A3: B | B3: Bulk Storage | C3: 122 | D3: 9.39 | E3: 9 | F3: 3.86
A4: C | B4: Small Parts | C4: 120 | D4: 7.42 | E4: 7 | F4: 3.81
A5: D | B5: Fragile | C5: 122 | D5: 10.01 | E5: 10 | F5: 4
A6: E | B6: Fast-Moving | C6: 127 | D6: 5.76 | E6: 6 | F6: 3.62
A7: F | B7: Bulk Storage | C7: 124 | D7: 7.64 | E7: 8 | F7: 3.9
A8: G | B8: Cold Storage | C8: 131 | D8: 10.69 | E8: 11 | F8: 3.93
A9: H | B9: Small Parts | C9: 136 | D9: 6.35 | E9: 7 | F9: 4.05

Sheet Order_Size_Analysis
A1: order_size_group | B1: Pick_Records | C1: Avg_Pick_Min | D1: Median_Pick_Min
A2: Small (1-5) | B2: 259 | C2: 7.56 | D2: 7
A3: Medium (6-10) | B3: 387 | C3: 7.73 | D3: 8
A4: Large (11-20) | B4: 335 | C4: 8.01 | D4: 8
B5: 32 | C5: 7.69 | D5: 8

Sheet Shift_Analysis
A1: shift | B1: Pick_Records | C1: Avg_Pick_Min | D1: Median_Pick_Min | E1: Avg_Quantity
A2: Evening | B2: 96 | C2: 8.65 | D2: 9 | E2: 4.01
A3: Morning | B3: 177 | C3: 7.34 | D3: 7 | E3: 3.76
A4: Night | B4: 583 | C4: 7.8 | D4: 8 | E4: 3.91
A5: Unknown | B5: 157 | C5: 7.65 | D5: 7 | E5: 3.78

Sheet Experience_Analysis
A1: experience_band | B1: Pick_Records | C1: Avg_Pick_Min | D1: Median_Pick_Min
A2: Beginner | B2: 184 | C2: 9.57 | D2: 9
A3: Experienced | B3: 272 | C3: 6.74 | D3: 7
A4: Intermediate | B4: 324 | C4: 7.69 | D4: 8
A5: Unknown | B5: 233 | C5: 7.7 | D5: 7

Sheet Category_Analysis
A1: category | B1: Pick_Records | C1: Avg_Pick_Min | D1: Median_Pick_Min | E1: Avg_Quantity
A2: Apparel | B2: 114 | C2: 7.93 | D2: 8 | E2: 3.98
A3: Bulk Materials | B3: 208 | C3: 7.53 | D3: 7.5 | E3: 3.79
A4: Electronics | B4: 166 | C4: 7.62 | D4: 7 | E4: 3.93
A5: Fragile Goods | B5: 154 | C5: 8.08 | D5: 7.5 | E5: 4.08
A6: Home Goods | B6: 99 | C6: 7.73 | D6: 7 | E6: 3.93
A7: Small Parts | B7: 164 | C7: 7.84 | D7: 8 | E7: 3.7
A8: Unknown | B8: 108 | C8: 7.83 | D8: 8 | E8: 3.79

Sheet Hourly_Analysis
A1: start_hour | B1: Pick_Records | C1: Avg_Pick_Min
A2: 0 | B2: 40 | C2: 6.85
A3: 1 | B3: 56 | C3: 7.38
A4: 2 | B4: 36 | C4: 8.31
A5: 3 | B5: 52 | C5: 7.17
A6: 4 | B6: 28 | C6: 8.29
A7: 5 | B7: 39 | C7: 7.82
A8: 6 | B8: 31 | C8: 8.16
A9: 7 | B9: 38 | C9: 8
A10: 8 | B10: 41 | C10: 7.8
A11: 9 | B11: 58 | C11: 7.79
A12: 10 | B12: 55 | C12: 7.8
A13: 11 | B13: 38 | C13: 7.74
... A25: 23 | B25: 38 | C25: 6.84

Sheet Order_Audit
A1: order_id | B1: item_count | C1: priority | D1: order_timestamp
A2: O00022 | B2: 6 | C2: Urgent | D2: 46270.611
A3: O00022 | B3: 99 | C3: Urgent | D3: 46280.5

Sheet Pick_Audit
A1: pick_id | B1: order_id | C1: picker_id | D1: zone_id | E1: item_id | F1: start_time | G1: finish_time | H1: quantity | I1: pick_time_min | J1: missing_timestamp | K1: negative_duration | L1: invalid_quantity
A2: P000046 | B2: O00014 | C2: W026 | D2: C | E2: I0064 | F2: 46290.287 | G2: 46290.291 | H2: 4 | I2: 6 | J2: FALSE | K2: FALSE | L2: FALSE
A3: P000046 | B3: O00014 | C3: W026 | D3: C | E3: I0064 | F3: 46290.287 | G3: 46285.999 | H3: 4 | I3: -6174 | J3: FALSE | K3: TRUE | L3: FALSE

Sheet Worker_Audit
A1: picker_id | B1: shift | C1: experience_band
A2: W007 | B2: Night
A3: W007 | B3: Night | C3: Intermediate

Sheet Zone_Audit
A1: zone_id | B1: zone_type | C1: distance_band
A2: B | B2: Bulk | C2: Far
A3: B | B3: Bulk Storage | C3: Far

Sheet Formula_Comparisons
A1: Analysis | B1: Group | C1: Pick Records | D1: Average Pick Time (min) | E1: Median Pick Time (min) | F1: Average Quantity
A2: Zone | B2: A | C2: =COUNTIF(Cleaned_Data!$D:$D,B2) -> 131 | D2: =IFERROR(AVERAGEIF(Cleaned_Data!$D:$D,B2,Cleaned_Data!$I:$I),0) -> 5.1832061 | E2: =IFERROR(VLOOKUP(B2,Zone_Analysis!$A:$F,5,FALSE),0) -> 5 | F2: =IFERROR(AVERAGEIF(Cleaned_Data!$D:$D,B2,Cleaned_Data!$H:$H),0) -> 3.8167939
A3: Zone | B3: B | C3: =COUNTIF(Cleaned_Data!$D:$D,B3) -> 122 | D3: =IFERROR(AVERAGEIF(Cleaned_Data!$D:$D,B3,Cleaned_Data!$I:$I),0) -> 9.3934426 | E3: =IFERROR(VLOOKUP(B3,Zone_Analysis!$A:$F,5,FALSE),0) -> 9 | F3: =IFERROR(AVERAGEIF(Cleaned_Data!$D:$D,B3,Cleaned_Data!$H:$H),0) -> 3.8606557
